// src/core/computation/computationRecovery.ts

/**
 * Service for recovering from failed calculations
 * by implementing retry mechanisms and fallback strategies.
 * 
 * @todo Implement full recovery functionality
 */
export class ComputationRecoveryService {
    private maxRetries: number;
    private retryDelay: number;
    
    constructor(maxRetries: number = 3, retryDelay: number = 1000) {
      this.maxRetries = maxRetries;
      this.retryDelay = retryDelay;
    }
    
    /**
     * Attempts to execute a calculation with retry logic
     * 
     * @param calculationFn The function to execute
     * @param fallbackFn Optional fallback function if all retries fail
     */
    public async executeWithRecovery<T>(
      calculationFn: () => Promise<T>,
      fallbackFn?: () => Promise<T>
    ): Promise<T> {
      let lastError: Error | null = null;
      
      for (let attempt = 0; attempt < this.maxRetries; attempt++) {
        try {
          return await calculationFn();
        } catch (error) {
          lastError = error instanceof Error ? error : new Error(String(error));
          console.warn(`Calculation attempt ${attempt + 1} failed: ${lastError.message}`);
          
          if (attempt < this.maxRetries - 1) {
            await this.delay(this.retryDelay * Math.pow(2, attempt)); // Exponential backoff
          }
        }
      }
      
      if (fallbackFn) {
        console.warn('All retry attempts failed, using fallback calculation');
        try {
          return await fallbackFn();
        } catch (fallbackError) {
          throw new Error(`Main calculation and fallback both failed. Original error: ${lastError?.message}`);
        }
      }
      
      throw lastError || new Error('Calculation failed for unknown reason');
    }
    
    private delay(ms: number): Promise<void> {
      return new Promise(resolve => setTimeout(resolve, ms));
    }
  }
  
  // Export a default instance
  export const computationRecovery = new ComputationRecoveryService();